2022-05-20 12:19:48.819026: W tensorflow/stream_executor/platform/default/dso_loader.cc:64] Could not load dynamic library 'libcudart.so.11.0'; dlerror: libcudart.so.11.0: cannot open shared object file: No such file or directory
2022-05-20 12:19:48.819072: I tensorflow/stream_executor/cuda/cudart_stub.cc:29] Ignore above cudart dlerror if you do not have a GPU set up on your machine.
2022-05-20 12:19:50.567164: W tensorflow/stream_executor/platform/default/dso_loader.cc:64] Could not load dynamic library 'libcudart.so.11.0'; dlerror: libcudart.so.11.0: cannot open shared object file: No such file or directory
2022-05-20 12:19:50.567269: W tensorflow/stream_executor/platform/default/dso_loader.cc:64] Could not load dynamic library 'libcublas.so.11'; dlerror: libcublas.so.11: cannot open shared object file: No such file or directory
2022-05-20 12:19:50.567331: W tensorflow/stream_executor/platform/default/dso_loader.cc:64] Could not load dynamic library 'libcublasLt.so.11'; dlerror: libcublasLt.so.11: cannot open shared object file: No such file or directory
2022-05-20 12:19:50.567388: W tensorflow/stream_executor/platform/default/dso_loader.cc:64] Could not load dynamic library 'libcufft.so.10'; dlerror: libcufft.so.10: cannot open shared object file: No such file or directory
2022-05-20 12:19:50.567443: W tensorflow/stream_executor/platform/default/dso_loader.cc:64] Could not load dynamic library 'libcurand.so.10'; dlerror: libcurand.so.10: cannot open shared object file: No such file or directory
2022-05-20 12:19:50.567499: W tensorflow/stream_executor/platform/default/dso_loader.cc:64] Could not load dynamic library 'libcusolver.so.11'; dlerror: libcusolver.so.11: cannot open shared object file: No such file or directory
2022-05-20 12:19:50.567553: W tensorflow/stream_executor/platform/default/dso_loader.cc:64] Could not load dynamic library 'libcusparse.so.11'; dlerror: libcusparse.so.11: cannot open shared object file: No such file or directory
2022-05-20 12:19:50.567608: W tensorflow/stream_executor/platform/default/dso_loader.cc:64] Could not load dynamic library 'libcudnn.so.8'; dlerror: libcudnn.so.8: cannot open shared object file: No such file or directory
2022-05-20 12:19:50.567626: W tensorflow/core/common_runtime/gpu/gpu_device.cc:1835] Cannot dlopen some GPU libraries. Please make sure the missing libraries mentioned above are installed properly if you would like to use GPU. Follow the guide at https://www.tensorflow.org/install/gpu for how to download and setup the required libraries for your platform.
Skipping registering GPU devices...
2022-05-20 12:21:35.980297: I tensorflow/core/platform/cpu_feature_guard.cc:142] This TensorFlow binary is optimized with oneAPI Deep Neural Network Library (oneDNN) to use the following CPU instructions in performance-critical operations:  AVX2 FMA
To enable them in other operations, rebuild TensorFlow with the appropriate compiler flags.
tf:  2.6.0
/home/chau/workingdir/tf_implementations/bash_scripts
{'batchSize': 4.0, 'numTrainingSteps': 320000.0, 'beta1': 0.974833, 'beta2': 0.99689, 'epsilon': 0.00388, 'decayDurationFactor': 0.979079, 'initialLearningRate': 0.002798, 'learningRateDecay': 0.001025, 'glorotScaleFactor': 0.1, 'orthogonalScaleFactor': 0.1, 'testSize': 0.5, 'noUnits': 81, 'timestep': 40}
float64
Traceback (most recent call last):
  File "../pythons/new_neurons/run/best22_v0.py", line 264, in <module>
    model = rnn_plus_model(noIn, noOut, timestep=hyperparams['timestep'])
  File "../pythons/new_neurons/run/best22_v0.py", line 228, in rnn_plus_model
    model.add(tf.keras.layers.RNN(cell=RNN_plus_v1_cell(units=hyperparams['noUnits']), input_shape=[timestep, noInput], unroll=False, name='RNNp_layer', dtype=DTYPE))
  File "/home/anaconda3/lib/python3.7/site-packages/tensorflow/python/training/tracking/base.py", line 530, in _method_wrapper
    result = method(self, *args, **kwargs)
  File "/home/anaconda3/lib/python3.7/site-packages/keras/engine/sequential.py", line 202, in add
    layer(x)
  File "/home/anaconda3/lib/python3.7/site-packages/keras/layers/recurrent.py", line 659, in __call__
    return super(RNN, self).__call__(inputs, **kwargs)
  File "/home/anaconda3/lib/python3.7/site-packages/keras/engine/base_layer.py", line 977, in __call__
    input_list)
  File "/home/anaconda3/lib/python3.7/site-packages/keras/engine/base_layer.py", line 1115, in _functional_construction_call
    inputs, input_masks, args, kwargs)
  File "/home/anaconda3/lib/python3.7/site-packages/keras/engine/base_layer.py", line 848, in _keras_tensor_symbolic_call
    return self._infer_output_signature(inputs, args, kwargs, input_masks)
  File "/home/anaconda3/lib/python3.7/site-packages/keras/engine/base_layer.py", line 886, in _infer_output_signature
    self._maybe_build(inputs)
  File "/home/anaconda3/lib/python3.7/site-packages/keras/engine/base_layer.py", line 2659, in _maybe_build
    self.build(input_shapes)  # pylint:disable=not-callable
  File "/home/anaconda3/lib/python3.7/site-packages/keras/layers/recurrent.py", line 577, in build
    self.cell.build(step_input_shape)
  File "../pythons/new_neurons/run/best22_v0.py", line 161, in build
    self.kernel = self.add_weight(shape=(input_dim, self.units), name='w_input', initializer=self.kernel_initializer, regularizer=None, constraint=None, dtype=self.cell_dtype)
AttributeError: 'RNN_plus_v1_cell' object has no attribute 'cell_dtype'
