2022-05-20 12:19:48.805232: W tensorflow/stream_executor/platform/default/dso_loader.cc:64] Could not load dynamic library 'libcudart.so.11.0'; dlerror: libcudart.so.11.0: cannot open shared object file: No such file or directory
2022-05-20 12:19:48.805287: I tensorflow/stream_executor/cuda/cudart_stub.cc:29] Ignore above cudart dlerror if you do not have a GPU set up on your machine.
2022-05-20 12:19:50.722816: W tensorflow/stream_executor/platform/default/dso_loader.cc:64] Could not load dynamic library 'libcudart.so.11.0'; dlerror: libcudart.so.11.0: cannot open shared object file: No such file or directory
2022-05-20 12:19:50.722921: W tensorflow/stream_executor/platform/default/dso_loader.cc:64] Could not load dynamic library 'libcublas.so.11'; dlerror: libcublas.so.11: cannot open shared object file: No such file or directory
2022-05-20 12:19:50.722978: W tensorflow/stream_executor/platform/default/dso_loader.cc:64] Could not load dynamic library 'libcublasLt.so.11'; dlerror: libcublasLt.so.11: cannot open shared object file: No such file or directory
2022-05-20 12:19:50.723033: W tensorflow/stream_executor/platform/default/dso_loader.cc:64] Could not load dynamic library 'libcufft.so.10'; dlerror: libcufft.so.10: cannot open shared object file: No such file or directory
2022-05-20 12:19:50.723087: W tensorflow/stream_executor/platform/default/dso_loader.cc:64] Could not load dynamic library 'libcurand.so.10'; dlerror: libcurand.so.10: cannot open shared object file: No such file or directory
2022-05-20 12:19:50.723141: W tensorflow/stream_executor/platform/default/dso_loader.cc:64] Could not load dynamic library 'libcusolver.so.11'; dlerror: libcusolver.so.11: cannot open shared object file: No such file or directory
2022-05-20 12:19:50.723191: W tensorflow/stream_executor/platform/default/dso_loader.cc:64] Could not load dynamic library 'libcusparse.so.11'; dlerror: libcusparse.so.11: cannot open shared object file: No such file or directory
2022-05-20 12:19:50.723255: W tensorflow/stream_executor/platform/default/dso_loader.cc:64] Could not load dynamic library 'libcudnn.so.8'; dlerror: libcudnn.so.8: cannot open shared object file: No such file or directory
2022-05-20 12:19:50.723273: W tensorflow/core/common_runtime/gpu/gpu_device.cc:1835] Cannot dlopen some GPU libraries. Please make sure the missing libraries mentioned above are installed properly if you would like to use GPU. Follow the guide at https://www.tensorflow.org/install/gpu for how to download and setup the required libraries for your platform.
Skipping registering GPU devices...
2022-05-20 12:21:59.794366: I tensorflow/core/platform/cpu_feature_guard.cc:142] This TensorFlow binary is optimized with oneAPI Deep Neural Network Library (oneDNN) to use the following CPU instructions in performance-critical operations:  AVX2 FMA
To enable them in other operations, rebuild TensorFlow with the appropriate compiler flags.
2022-05-20 12:22:00.156774: I tensorflow/compiler/mlir/mlir_graph_optimization_pass.cc:185] None of the MLIR Optimization Passes are enabled (registered 2)
tf:  2.6.0
/home/chau/workingdir/tf_implementations/bash_scripts
{'batchSize': 4.0, 'numTrainingSteps': 320000.0, 'beta1': 0.974833, 'beta2': 0.99689, 'epsilon': 0.00388, 'decayDurationFactor': 0.979079, 'initialLearningRate': 0.002798, 'learningRateDecay': 0.001025, 'glorotScaleFactor': 0.1, 'orthogonalScaleFactor': 0.1, 'testSize': 0.5, 'noUnits': 81, 'timestep': 40}
Step 1: Dividing the training and testing set with ratio 1:1 (50%).
Epoch 1/23
Traceback (most recent call last):
  File "../pythons/new_neurons/run/lstm_v0.py", line 145, in <module>
    use_multiprocessing=False,
  File "/home/anaconda3/lib/python3.7/site-packages/keras/engine/training.py", line 1184, in fit
    tmp_logs = self.train_function(iterator)
  File "/home/anaconda3/lib/python3.7/site-packages/tensorflow/python/eager/def_function.py", line 885, in __call__
    result = self._call(*args, **kwds)
  File "/home/anaconda3/lib/python3.7/site-packages/tensorflow/python/eager/def_function.py", line 933, in _call
    self._initialize(args, kwds, add_initializers_to=initializers)
  File "/home/anaconda3/lib/python3.7/site-packages/tensorflow/python/eager/def_function.py", line 760, in _initialize
    *args, **kwds))
  File "/home/anaconda3/lib/python3.7/site-packages/tensorflow/python/eager/function.py", line 3066, in _get_concrete_function_internal_garbage_collected
    graph_function, _ = self._maybe_define_function(args, kwargs)
  File "/home/anaconda3/lib/python3.7/site-packages/tensorflow/python/eager/function.py", line 3463, in _maybe_define_function
    graph_function = self._create_graph_function(args, kwargs)
  File "/home/anaconda3/lib/python3.7/site-packages/tensorflow/python/eager/function.py", line 3308, in _create_graph_function
    capture_by_value=self._capture_by_value),
  File "/home/anaconda3/lib/python3.7/site-packages/tensorflow/python/framework/func_graph.py", line 1007, in func_graph_from_py_func
    func_outputs = python_func(*func_args, **func_kwargs)
  File "/home/anaconda3/lib/python3.7/site-packages/tensorflow/python/eager/def_function.py", line 668, in wrapped_fn
    out = weak_wrapped_fn().__wrapped__(*args, **kwds)
  File "/home/anaconda3/lib/python3.7/site-packages/tensorflow/python/framework/func_graph.py", line 994, in wrapper
    raise e.ag_error_metadata.to_exception(e)
TypeError: in user code:

    /home/anaconda3/lib/python3.7/site-packages/keras/engine/training.py:853 train_function  *
        return step_function(self, iterator)
    /home/anaconda3/lib/python3.7/site-packages/keras/engine/training.py:842 step_function  **
        outputs = model.distribute_strategy.run(run_step, args=(data,))
    /home/anaconda3/lib/python3.7/site-packages/tensorflow/python/distribute/distribute_lib.py:1286 run
        return self._extended.call_for_each_replica(fn, args=args, kwargs=kwargs)
    /home/anaconda3/lib/python3.7/site-packages/tensorflow/python/distribute/distribute_lib.py:2849 call_for_each_replica
        return self._call_for_each_replica(fn, args, kwargs)
    /home/anaconda3/lib/python3.7/site-packages/tensorflow/python/distribute/distribute_lib.py:3632 _call_for_each_replica
        return fn(*args, **kwargs)
    /home/anaconda3/lib/python3.7/site-packages/keras/engine/training.py:835 run_step  **
        outputs = model.train_step(data)
    /home/anaconda3/lib/python3.7/site-packages/keras/engine/training.py:791 train_step
        self.optimizer.minimize(loss, self.trainable_variables, tape=tape)
    /home/anaconda3/lib/python3.7/site-packages/keras/optimizer_v2/optimizer_v2.py:522 minimize
        return self.apply_gradients(grads_and_vars, name=name)
    /home/anaconda3/lib/python3.7/site-packages/keras/optimizer_v2/optimizer_v2.py:652 apply_gradients
        apply_state = self._prepare(var_list)
    /home/anaconda3/lib/python3.7/site-packages/keras/optimizer_v2/optimizer_v2.py:934 _prepare
        self._prepare_local(var_device, var_dtype, apply_state)
    /home/anaconda3/lib/python3.7/site-packages/keras/optimizer_v2/adam.py:125 _prepare_local
        super(Adam, self)._prepare_local(var_device, var_dtype, apply_state)
    /home/anaconda3/lib/python3.7/site-packages/keras/optimizer_v2/optimizer_v2.py:940 _prepare_local
        lr_t = tf.identity(self._decayed_lr(var_dtype))
    /home/anaconda3/lib/python3.7/site-packages/keras/optimizer_v2/optimizer_v2.py:997 _decayed_lr
        lr_t = tf.cast(lr_t(local_step), var_dtype)
    ../pythons/new_neurons/run/lstm_v0.py:82 __call__
        self.lr = tf.cond(self.step > self.T,
    /home/anaconda3/lib/python3.7/site-packages/tensorflow/python/ops/math_ops.py:1817 wrapper
        return fn(x, y, *args, **kwargs)
    /home/anaconda3/lib/python3.7/site-packages/tensorflow/python/ops/gen_math_ops.py:4896 less
        "Less", x=x, y=y, name=name)
    /home/anaconda3/lib/python3.7/site-packages/tensorflow/python/framework/op_def_library.py:558 _apply_op_helper
        inferred_from[input_arg.type_attr]))

    TypeError: Input 'y' of 'Less' Op has type float64 that does not match type float32 of argument 'x'.

